02/09/21 (22:56:18) | ERROR: Input thread failed with exception: (5, 'Input/output error')
Traceback (most recent call last):
  File "/usr/bin/bpytop", line 985, in _get_key
    input_key = ""
  File "/usr/bin/bpytop", line 778, in __exit__
    termios.tcsetattr(self.stream, termios.TCSANOW, self.original_stty)
termios.error: (5, 'Input/output error')
02/09/21 (23:11:13) | ERROR: Input thread failed with exception: (5, 'Input/output error')
Traceback (most recent call last):
  File "/usr/bin/bpytop", line 985, in _get_key
    input_key = ""
  File "/usr/bin/bpytop", line 778, in __exit__
    termios.tcsetattr(self.stream, termios.TCSANOW, self.original_stty)
termios.error: (5, 'Input/output error')
02/09/21 (23:55:41) | ERROR: [Errno 5] Input/output error
Traceback (most recent call last):
  File "/usr/bin/bpytop", line 5657, in main
    run()
  File "/usr/bin/bpytop", line 5650, in run
    if Key.input_wait(Timer.left()):
  File "/usr/bin/bpytop", line 911, in input_wait
    cls.new.wait(sec if sec > 0 else 0.0)
  File "/usr/lib/python3.9/threading.py", line 574, in wait
    signaled = self._cond.wait(timeout)
  File "/usr/lib/python3.9/threading.py", line 316, in wait
    gotit = waiter.acquire(True, timeout)
  File "/usr/bin/bpytop", line 5218, in now_awake
    Draw.now(Term.alt_screen, Term.clear, Term.hide_cursor, Term.mouse_on, Term.title("BpyTOP"))
  File "/usr/bin/bpytop", line 1019, in now
    print(*args, sep="", end="", flush=True)
OSError: [Errno 5] Input/output error
02/09/21 (23:55:41) | ERROR: Input thread failed with exception: (5, 'Input/output error')
Traceback (most recent call last):
  File "/usr/bin/bpytop", line 985, in _get_key
    input_key = ""
  File "/usr/bin/bpytop", line 778, in __exit__
    termios.tcsetattr(self.stream, termios.TCSANOW, self.original_stty)
termios.error: (5, 'Input/output error')
03/09/21 (02:13:16) | ERROR: [Errno 5] Input/output error
Traceback (most recent call last):
  File "/usr/bin/bpytop", line 5657, in main
    run()
  File "/usr/bin/bpytop", line 5650, in run
    if Key.input_wait(Timer.left()):
  File "/usr/bin/bpytop", line 911, in input_wait
    cls.new.wait(sec if sec > 0 else 0.0)
  File "/usr/lib/python3.9/threading.py", line 574, in wait
    signaled = self._cond.wait(timeout)
  File "/usr/lib/python3.9/threading.py", line 316, in wait
    gotit = waiter.acquire(True, timeout)
  File "/usr/bin/bpytop", line 5218, in now_awake
    Draw.now(Term.alt_screen, Term.clear, Term.hide_cursor, Term.mouse_on, Term.title("BpyTOP"))
  File "/usr/bin/bpytop", line 1019, in now
    print(*args, sep="", end="", flush=True)
OSError: [Errno 5] Input/output error
03/09/21 (02:13:16) | ERROR: Input thread failed with exception: (5, 'Input/output error')
Traceback (most recent call last):
  File "/usr/bin/bpytop", line 985, in _get_key
    input_key = ""
  File "/usr/bin/bpytop", line 778, in __exit__
    termios.tcsetattr(self.stream, termios.TCSANOW, self.original_stty)
termios.error: (5, 'Input/output error')
03/09/21 (11:26:48) | ERROR: Data collection thread failed with exception: 'pid'
Traceback (most recent call last):
  File "/usr/bin/bpytop", line 2939, in _runner
    collector._draw()
  File "/usr/bin/bpytop", line 3971, in _draw
    ProcBox._draw_fg()
  File "/usr/bin/bpytop", line 2618, in _draw_fg
    f'{Mv.to(dy-1, x+1)}{THEME.proc_box(Symbol.title_left)}{Fx.b}{THEME.title(str(proc.details["pid"]))}{Fx.ub}{THEME.proc_box(Symbol.title_right)}'
KeyError: 'pid'
03/09/21 (11:26:49) | WARNING: Exiting with errorcode (1). Runtime 0:04:18 

03/09/21 (11:27:04) | ERROR: Data collection thread failed with exception: 'pid'
Traceback (most recent call last):
  File "/usr/bin/bpytop", line 2939, in _runner
    collector._draw()
  File "/usr/bin/bpytop", line 3971, in _draw
    ProcBox._draw_fg()
  File "/usr/bin/bpytop", line 2618, in _draw_fg
    f'{Mv.to(dy-1, x+1)}{THEME.proc_box(Symbol.title_left)}{Fx.b}{THEME.title(str(proc.details["pid"]))}{Fx.ub}{THEME.proc_box(Symbol.title_right)}'
KeyError: 'pid'
03/09/21 (11:27:05) | WARNING: Exiting with errorcode (1). Runtime 0:00:12 

03/09/21 (12:02:39) | ERROR: Exception when sending signal 9 to pid 10
03/09/21 (12:02:39) | ERROR: [Errno 1] Operation not permitted
Traceback (most recent call last):
  File "/usr/bin/bpytop", line 5459, in process_keys
    os.kill(pid, sig)
PermissionError: [Errno 1] Operation not permitted
